[2024-07-23T17:39:07.105+0000] {local_task_job_runner.py:120} INFO - ::group::Pre task execution logs
[2024-07-23T17:39:07.199+0000] {taskinstance.py:2076} INFO - Dependencies all met for dep_context=non-requeueable deps ti=<TaskInstance: hackaton_dag.hackaton_task manual__2024-07-23T17:36:50.396578+00:00 [queued]>
[2024-07-23T17:39:07.218+0000] {taskinstance.py:2076} INFO - Dependencies all met for dep_context=requeueable deps ti=<TaskInstance: hackaton_dag.hackaton_task manual__2024-07-23T17:36:50.396578+00:00 [queued]>
[2024-07-23T17:39:07.220+0000] {taskinstance.py:2306} INFO - Starting attempt 2 of 2
[2024-07-23T17:39:07.250+0000] {taskinstance.py:2330} INFO - Executing <Task(BashOperator): hackaton_task> on 2024-07-23 17:36:50.396578+00:00
[2024-07-23T17:39:07.258+0000] {standard_task_runner.py:90} INFO - Running: ['***', 'tasks', 'run', 'hackaton_dag', 'hackaton_task', 'manual__2024-07-23T17:36:50.396578+00:00', '--job-id', '12', '--raw', '--subdir', 'DAGS_FOLDER/dag_script.py', '--cfg-path', '/tmp/tmp9w64h26w']
[2024-07-23T17:39:07.263+0000] {standard_task_runner.py:91} INFO - Job 12: Subtask hackaton_task
[2024-07-23T17:39:07.267+0000] {logging_mixin.py:188} WARNING - /home/***/.local/lib/python3.12/site-packages/***/task/task_runner/standard_task_runner.py:62 DeprecationWarning: This process (pid=849) is multi-threaded, use of fork() may lead to deadlocks in the child.
[2024-07-23T17:39:07.268+0000] {standard_task_runner.py:64} INFO - Started process 850 to run task
[2024-07-23T17:39:07.343+0000] {task_command.py:426} INFO - Running <TaskInstance: hackaton_dag.hackaton_task manual__2024-07-23T17:36:50.396578+00:00 [running]> on host beb4e5ba0df4
[2024-07-23T17:39:07.475+0000] {taskinstance.py:2648} INFO - Exporting env vars: AIRFLOW_CTX_DAG_OWNER='***' AIRFLOW_CTX_DAG_ID='hackaton_dag' AIRFLOW_CTX_TASK_ID='hackaton_task' AIRFLOW_CTX_EXECUTION_DATE='2024-07-23T17:36:50.396578+00:00' AIRFLOW_CTX_TRY_NUMBER='2' AIRFLOW_CTX_DAG_RUN_ID='manual__2024-07-23T17:36:50.396578+00:00'
[2024-07-23T17:39:07.476+0000] {taskinstance.py:430} INFO - ::endgroup::
[2024-07-23T17:39:07.497+0000] {subprocess.py:63} INFO - Tmp dir root location: /tmp
[2024-07-23T17:39:07.500+0000] {subprocess.py:75} INFO - Running command: ['/usr/bin/bash', '-c', 'python etl_script.py']
[2024-07-23T17:39:07.515+0000] {subprocess.py:86} INFO - Output:
[2024-07-23T17:39:07.605+0000] {subprocess.py:93} INFO - python: can't open file '/tmp/***tmpkqgwigz6/etl_script.py': [Errno 2] No such file or directory
[2024-07-23T17:39:07.610+0000] {subprocess.py:97} INFO - Command exited with return code 2
[2024-07-23T17:39:07.612+0000] {taskinstance.py:441} INFO - ::group::Post task execution logs
[2024-07-23T17:39:07.627+0000] {taskinstance.py:2905} ERROR - Task failed with exception
Traceback (most recent call last):
  File "/home/airflow/.local/lib/python3.12/site-packages/airflow/models/taskinstance.py", line 465, in _execute_task
    result = _execute_callable(context=context, **execute_callable_kwargs)
             ^^^^^^^^^^^^^^^^^^^^^^^^^^^^^^^^^^^^^^^^^^^^^^^^^^^^^^^^^^^^^
  File "/home/airflow/.local/lib/python3.12/site-packages/airflow/models/taskinstance.py", line 432, in _execute_callable
    return execute_callable(context=context, **execute_callable_kwargs)
           ^^^^^^^^^^^^^^^^^^^^^^^^^^^^^^^^^^^^^^^^^^^^^^^^^^^^^^^^^^^^
  File "/home/airflow/.local/lib/python3.12/site-packages/airflow/models/baseoperator.py", line 401, in wrapper
    return func(self, *args, **kwargs)
           ^^^^^^^^^^^^^^^^^^^^^^^^^^^
  File "/home/airflow/.local/lib/python3.12/site-packages/airflow/operators/bash.py", line 243, in execute
    raise AirflowException(
airflow.exceptions.AirflowException: Bash command failed. The command returned a non-zero exit code 2.
[2024-07-23T17:39:07.635+0000] {taskinstance.py:1206} INFO - Marking task as FAILED. dag_id=hackaton_dag, task_id=hackaton_task, run_id=manual__2024-07-23T17:36:50.396578+00:00, execution_date=20240723T173650, start_date=20240723T173907, end_date=20240723T173907
[2024-07-23T17:39:07.661+0000] {standard_task_runner.py:110} ERROR - Failed to execute job 12 for task hackaton_task (Bash command failed. The command returned a non-zero exit code 2.; 850)
[2024-07-23T17:39:07.684+0000] {local_task_job_runner.py:243} INFO - Task exited with return code 1
[2024-07-23T17:39:07.707+0000] {taskinstance.py:3503} INFO - 0 downstream tasks scheduled from follow-on schedule check
[2024-07-23T17:39:07.711+0000] {local_task_job_runner.py:222} INFO - ::endgroup::
