[2024-07-23T17:39:19.176+0000] {local_task_job_runner.py:120} INFO - ::group::Pre task execution logs
[2024-07-23T17:39:19.224+0000] {taskinstance.py:2076} INFO - Dependencies all met for dep_context=non-requeueable deps ti=<TaskInstance: hackaton_dag.hackaton_task manual__2024-07-23T17:36:50.396578+00:00 [queued]>
[2024-07-23T17:39:19.239+0000] {taskinstance.py:2076} INFO - Dependencies all met for dep_context=requeueable deps ti=<TaskInstance: hackaton_dag.hackaton_task manual__2024-07-23T17:36:50.396578+00:00 [queued]>
[2024-07-23T17:39:19.241+0000] {taskinstance.py:2306} INFO - Starting attempt 3 of 3
[2024-07-23T17:39:19.265+0000] {taskinstance.py:2330} INFO - Executing <Task(BashOperator): hackaton_task> on 2024-07-23 17:36:50.396578+00:00
[2024-07-23T17:39:19.273+0000] {standard_task_runner.py:90} INFO - Running: ['***', 'tasks', 'run', 'hackaton_dag', 'hackaton_task', 'manual__2024-07-23T17:36:50.396578+00:00', '--job-id', '13', '--raw', '--subdir', 'DAGS_FOLDER/dag_script.py', '--cfg-path', '/tmp/tmpz6ri8hui']
[2024-07-23T17:39:19.278+0000] {standard_task_runner.py:91} INFO - Job 13: Subtask hackaton_task
[2024-07-23T17:39:19.281+0000] {logging_mixin.py:188} WARNING - /home/***/.local/lib/python3.12/site-packages/***/task/task_runner/standard_task_runner.py:62 DeprecationWarning: This process (pid=852) is multi-threaded, use of fork() may lead to deadlocks in the child.
[2024-07-23T17:39:19.282+0000] {standard_task_runner.py:64} INFO - Started process 853 to run task
[2024-07-23T17:39:19.347+0000] {task_command.py:426} INFO - Running <TaskInstance: hackaton_dag.hackaton_task manual__2024-07-23T17:36:50.396578+00:00 [running]> on host beb4e5ba0df4
[2024-07-23T17:39:19.465+0000] {taskinstance.py:2648} INFO - Exporting env vars: AIRFLOW_CTX_DAG_OWNER='***' AIRFLOW_CTX_DAG_ID='hackaton_dag' AIRFLOW_CTX_TASK_ID='hackaton_task' AIRFLOW_CTX_EXECUTION_DATE='2024-07-23T17:36:50.396578+00:00' AIRFLOW_CTX_TRY_NUMBER='3' AIRFLOW_CTX_DAG_RUN_ID='manual__2024-07-23T17:36:50.396578+00:00'
[2024-07-23T17:39:19.467+0000] {taskinstance.py:430} INFO - ::endgroup::
[2024-07-23T17:39:19.488+0000] {subprocess.py:63} INFO - Tmp dir root location: /tmp
[2024-07-23T17:39:19.490+0000] {subprocess.py:75} INFO - Running command: ['/usr/bin/bash', '-c', 'python etl_script.py']
[2024-07-23T17:39:19.505+0000] {subprocess.py:86} INFO - Output:
[2024-07-23T17:39:19.601+0000] {subprocess.py:93} INFO - python: can't open file '/tmp/***tmpj4o4c42y/etl_script.py': [Errno 2] No such file or directory
[2024-07-23T17:39:19.607+0000] {subprocess.py:97} INFO - Command exited with return code 2
[2024-07-23T17:39:19.609+0000] {taskinstance.py:441} INFO - ::group::Post task execution logs
[2024-07-23T17:39:19.623+0000] {taskinstance.py:2905} ERROR - Task failed with exception
Traceback (most recent call last):
  File "/home/airflow/.local/lib/python3.12/site-packages/airflow/models/taskinstance.py", line 465, in _execute_task
    result = _execute_callable(context=context, **execute_callable_kwargs)
             ^^^^^^^^^^^^^^^^^^^^^^^^^^^^^^^^^^^^^^^^^^^^^^^^^^^^^^^^^^^^^
  File "/home/airflow/.local/lib/python3.12/site-packages/airflow/models/taskinstance.py", line 432, in _execute_callable
    return execute_callable(context=context, **execute_callable_kwargs)
           ^^^^^^^^^^^^^^^^^^^^^^^^^^^^^^^^^^^^^^^^^^^^^^^^^^^^^^^^^^^^
  File "/home/airflow/.local/lib/python3.12/site-packages/airflow/models/baseoperator.py", line 401, in wrapper
    return func(self, *args, **kwargs)
           ^^^^^^^^^^^^^^^^^^^^^^^^^^^
  File "/home/airflow/.local/lib/python3.12/site-packages/airflow/operators/bash.py", line 243, in execute
    raise AirflowException(
airflow.exceptions.AirflowException: Bash command failed. The command returned a non-zero exit code 2.
[2024-07-23T17:39:19.631+0000] {taskinstance.py:1206} INFO - Marking task as FAILED. dag_id=hackaton_dag, task_id=hackaton_task, run_id=manual__2024-07-23T17:36:50.396578+00:00, execution_date=20240723T173650, start_date=20240723T173919, end_date=20240723T173919
[2024-07-23T17:39:19.655+0000] {standard_task_runner.py:110} ERROR - Failed to execute job 13 for task hackaton_task (Bash command failed. The command returned a non-zero exit code 2.; 853)
[2024-07-23T17:39:19.700+0000] {local_task_job_runner.py:243} INFO - Task exited with return code 1
[2024-07-23T17:39:19.724+0000] {taskinstance.py:3503} INFO - 0 downstream tasks scheduled from follow-on schedule check
[2024-07-23T17:39:19.730+0000] {local_task_job_runner.py:222} INFO - ::endgroup::
